Workbook
Name ActualPct: 'Inputs & Assumptions'!$B$7
Name AnalysisEnd: 'Inputs & Assumptions'!$B$13
Name AnalysisStart: 'Inputs & Assumptions'!$B$12
Name BasisAssumed: 'Inputs & Assumptions'!$B$10
Name BasisLocked: 'Inputs & Assumptions'!$B$11
Name HedgePct: 'Inputs & Assumptions'!$B$8
Name ProdForecast: 'Inputs & Assumptions'!$B$6
Name SwapPrice: 'Inputs & Assumptions'!$B$9

Sheet Executive Summary
A1: Permian Crude Producer Hedge & Basis Risk Model
A2: Educational / student research project. Simplified hedge comparison for a hypothetical Permian Basin crude producer -- not financial advice.
A4: Purpose: | B4: Show how WTI benchmark price risk, Midland-Cushing basis risk, and production volume uncertainty affect a Permian producer's revenue, and how basic hedge strategies change that exposure.
A6: Core question: | B6: How do WTI prices, Midland basis, and production uncertainty affect a Permian producer's revenue, and how do basic hedge strategies change that exposure?
A8: Disclosure: | B8: The producer, production volumes, hedge percentages, swap price, and basis levels used here are entirely hypothetical and illustrative. Only the WTI Cushing spot price history is real, public EIA data.
A10: Strategy Comparison
A11: Strategy | B11: Avg. Net Realized Price ($/bbl) | C11: Avg. Monthly Net Revenue ($) | D11: Worst Monthly Net Revenue ($) | E11: Total Hedge P&L ($) | F11: Revenue Range ($)
A12: Unhedged | B12: ='Hedge Calculations'!B6 -> 72.862492 | C12: ='Hedge Calculations'!B7 -> 3351674.6 | D12: ='Hedge Calculations'!B8 -> 2567634.4 | E12: ='Hedge Calculations'!B10 -> 0 | F12: ='Hedge Calculations'!B9-'Hedge Calculations'!B8 -> 2017045.3
A13: WTI Fixed-Price Swap | B13: ='Hedge Calculations'!C6 -> 73.133763 | C13: ='Hedge Calculations'!C7 -> 3364153.1 | D13: ='Hedge Calculations'!C8 -> 3291409.4 | E13: ='Hedge Calculations'!C10 -> 449225 | F13: ='Hedge Calculations'!C9-'Hedge Calculations'!C8 -> 146789.11
A14: WTI Swap + Midland Basis Hedge | B14: ='Hedge Calculations'!D6 -> 73.91345 | C14: ='Hedge Calculations'!D7 -> 3400018.7 | D14: ='Hedge Calculations'!D8 -> 3340363.5 | E14: ='Hedge Calculations'!D10 -> 1740387.2 | F14: ='Hedge Calculations'!D9-'Hedge Calculations'!D8 -> 153470.84
A16: Key Findings
A17: - The WTI fixed-price swap tracks the benchmark closely, cutting the swing in net realized price that comes from WTI moving up or down.
A18: - Midland basis risk is not addressed by the WTI swap alone; only the combined strategy responds when the Midland discount widens or narrows.
A19: - Because the hedge is sized to forecast production, a production shortfall can leave part of the hedge unmatched by physical barrels (over-hedged volume).
A20: - The combined strategy is not a one-way win: it outperforms when Midland basis widens (base case, Stress B), but underperforms the WTI-only swap when the basis narrows instead (Stress D), since the basis hedge is locked at a fixed level rather than tracking the market both ways.
A21: Main Remaining Risk by Strategy
A22: Strategy | B22: Main Remaining Risk
A23: Unhedged | B23: Full exposure to both WTI price moves and Midland basis moves.
A24: WTI Fixed-Price Swap | B24: Midland basis risk remains; a wider discount still lowers realized price.
A25: WTI Swap + Basis Hedge | B25: Production-volume risk remains; a shortfall can create over-hedged volume.
A27: Conclusion
A28: Under the selected assumptions, the WTI swap reduces benchmark-price exposure, while the combined swap and basis hedge creates greater revenue stability. Production uncertainty remains important because hedging forecast volumes can create over-hedging. This is an educational, illustrative comparison, not a professional recommendation or an optimal hedge.

Sheet Inputs & Assumptions
A1: Inputs & Assumptions
A2: Hypothetical Permian Basin producer. All figures below are illustrative model assumptions, not current market quotes or a real hedge program.
A4: Illustrative Assumptions (edit the highlighted cells)
A5: Assumption | B5: Value | C5: Units | D5: Notes
A6: Monthly forecast production | B6: 50000 | C6: bbl/mo | D6: Planned monthly production for the hypothetical producer.
A7: Actual production (% of forecast) | B7: 0.92 | C7: % | D7: Illustrative production variance vs. forecast.
A8: Hedge percentage | B8: 0.85 | C8: % | D8: Share of forecast production hedged with the WTI swap.
A9: Fixed WTI swap price | B9: 75 | C9: $/bbl | D9: Illustrative fixed price on the WTI swap.
A10: Assumed Midland-Cushing basis | B10: -1.5 | C10: $/bbl | D10: Illustrative differential; not a live market quote.
A11: Locked Midland-Cushing basis level | B11: -1 | C11: $/bbl | D11: Basis level locked in by the basis hedge.
A12: Analysis start date | B12: 45108 | C12: date | D12: First month of the hedge comparison.
A13: Analysis end date | B13: 46174 | C13: date | D13: Last month of the hedge comparison.
A15: Observed Data
A16: Item | B16: Value | C16: Units | D16: Notes
A17: Historical WTI Cushing price | B17: See 'Historical WTI Data' tab | C17: $/bbl | D17: Real monthly-average data published by the EIA.
A19: Calculated Outputs (see 'Hedge Calculations' tab)
A20: Output | B20: Value | C20: Units | D20: Notes
A21: Avg. net realized price, combined strategy | B21: ='Hedge Calculations'!D6 -> 73.91345 | C21: $/bbl | D21: Average across the analysis window.
A22: Total hedge P&L, combined strategy | B22: ='Hedge Calculations'!D10 -> 1740387.2 | C22: $ | D22: WTI swap P&L plus basis hedge P&L, summed.
A23: Total over-hedged volume | B23: ='Hedge Calculations'!D11 -> 0 | C23: bbl | D23: Hedged volume exceeding actual production, summed.

Sheet Historical WTI Data
A1: Historical WTI Data
A2: Source data used to drive the hedge model below.
A4: Series name: | B4: Cushing, OK WTI Spot Price FOB (RWTC)
A5: Source: | B5: U.S. Energy Information Administration (EIA)
A6: Units: | B6: Dollars per barrel ($/bbl)
A7: Original frequency: | B7: Daily (aggregated by EIA to a monthly average)
A8: Aggregation method: | B8: EIA daily spot prices aggregated to a simple monthly average.
A9: Frequency used in workbook: | B9: Monthly average
A10: Date range: | B10: January 1986 - June 2026
A11: Retrieval date: | B11: 2026-07-14
A12: Source citation: | B12: U.S. Energy Information Administration (EIA) - https://www.eia.gov/dnav/pet/hist/RWTCM.htm
A14: Month | B14: WTI Cushing Price ($/bbl) | C14: Source | D14: Notes
A15: 31413 | B15: 22.93 | C15: U.S. Energy Information Administration (EIA)
A16: 31444 | B16: 15.46 | C16: U.S. Energy Information Administration (EIA)
A17: 31472 | B17: 12.61 | C17: U.S. Energy Information Administration (EIA)
A18: 31503 | B18: 12.84 | C18: U.S. Energy Information Administration (EIA)
A19: 31533 | B19: 15.38 | C19: U.S. Energy Information Administration (EIA)
A20: 31564 | B20: 13.43 | C20: U.S. Energy Information Administration (EIA)
A21: 31594 | B21: 11.59 | C21: U.S. Energy Information Administration (EIA)
A22: 31625 | B22: 15.1 | C22: U.S. Energy Information Administration (EIA)
A23: 31656 | B23: 14.87 | C23: U.S. Energy Information Administration (EIA)
A24: 31686 | B24: 14.9 | C24: U.S. Energy Information Administration (EIA)
A25: 31717 | B25: 15.22 | C25: U.S. Energy Information Administration (EIA)
A26: 31747 | B26: 16.11 | C26: U.S. Energy Information Administration (EIA)
... A500: 46174 | B500: 84.81 | C500: U.S. Energy Information Administration (EIA)

Sheet Hedge Calculations
A1: Hedge Calculations
A2: Monthly, formula-driven comparison of the three strategies over the analysis window.
A4: Summary Metrics
A5: Metric | B5: Unhedged | C5: WTI Swap | D5: Combined (Swap + Basis Hedge)
A6: Average net realized price ($/bbl) | B6: =AVERAGE(P14:P49) -> 72.862492 | C6: =AVERAGE(Q14:Q49) -> 73.133763 | D6: =AVERAGE(R14:R49) -> 73.91345
A7: Average monthly net revenue ($) | B7: =AVERAGE(K14:K49) -> 3351674.6 | C7: =AVERAGE(M14:M49) -> 3364153.1 | D7: =AVERAGE(O14:O49) -> 3400018.7
A8: Minimum monthly net revenue ($) | B8: =MIN(K14:K49) -> 2567634.4 | C8: =MIN(M14:M49) -> 3291409.4 | D8: =MIN(O14:O49) -> 3340363.5
A9: Maximum monthly net revenue ($) | B9: =MAX(K14:K49) -> 4584679.7 | C9: =MAX(M14:M49) -> 3438198.5 | D9: =MAX(O14:O49) -> 3493834.3
A10: Total hedge P&L ($) | B10: 0 | C10: =SUM(L14:L49) -> 449225 | D10: =SUM(L14:L49)+SUM(N14:N49) -> 1740387.2
A11: Total over-hedged volume (bbl) | B11: 0 | C11: =SUM(I14:I49) -> 0 | D11: =SUM(I14:I49) -> 0
A13: Date | B13: WTI Cushing Price ($/bbl) | C13: Assumed Midland Basis ($/bbl) | D13: Midland Physical Price ($/bbl) | E13: Forecast Production (bbl) | F13: Actual Production (bbl) | G13: Hedge % | H13: Hedged Volume (bbl) | I13: Over-Hedged Volume (bbl) | J13: Physical Revenue ($) | K13: Unhedged Net Revenue ($) | L13: WTI Swap P&L ($) | M13: WTI Swap Net Revenue ($) | N13: Basis Hedge P&L ($) | O13: Combined Net Revenue ($) | P13: Unhedged Net Realized Price ($/bbl) | Q13: WTI Swap Net Realized Price ($/bbl) | R13: Combined Net Realized Price ($/bbl)
A14: =AnalysisStart -> 45108 | B14: =INDEX('Historical WTI Data'!$B$15:$B$500,MATCH(A14,'Historical WTI Data'!$A$15:$A$500,0)) -> 76.07 | C14: =BasisAssumed - (ROW()-14)*0.02 + 0.3*SIN((ROW()-14)/3) -> -1.5 | D14: =B14+C14 -> 74.57 | E14: =ProdForecast -> 50000 | F14: =E14*ActualPct -> 46000 | G14: =HedgePct -> 0.85 | H14: =E14*G14 -> 42500 | I14: =MAX(H14-F14,0) -> 0 | J14: =F14*D14 -> 3430220 | K14: =J14 -> 3430220 | L14: =H14*(SwapPrice-B14) -> -45475 | M14: =J14+L14 -> 3384745 | N14: =H14*(BasisLocked-C14) -> 21250 | O14: =J14+L14+N14 -> 3405995 | P14: =IF(F14=0,0,K14/F14) -> 74.57 | Q14: =IF(F14=0,0,M14/F14) -> 73.581413 | R14: =IF(F14=0,0,O14/F14) -> 74.04337
A15: =EDATE($A$14,1) -> 45139 | B15: =INDEX('Historical WTI Data'!$B$15:$B$500,MATCH(A15,'Historical WTI Data'!$A$15:$A$500,0)) -> 81.39 | C15: =BasisAssumed - (ROW()-14)*0.02 + 0.3*SIN((ROW()-14)/3) -> -1.4218416 | D15: =B15+C15 -> 79.968158 | E15: =ProdForecast -> 50000 | F15: =E15*ActualPct -> 46000 | G15: =HedgePct -> 0.85 | H15: =E15*G15 -> 42500 | I15: =MAX(H15-F15,0) -> 0 | J15: =F15*D15 -> 3678535.3 | K15: =J15 -> 3678535.3 | L15: =H15*(SwapPrice-B15) -> -271575 | M15: =J15+L15 -> 3406960.3 | N15: =H15*(BasisLocked-C15) -> 17928.268 | O15: =J15+L15+N15 -> 3424888.6 | P15: =IF(F15=0,0,K15/F15) -> 79.968158 | Q15: =IF(F15=0,0,M15/F15) -> 74.064354 | R15: =IF(F15=0,0,O15/F15) -> 74.454099
A16: =EDATE($A$14,2) -> 45170 | B16: =INDEX('Historical WTI Data'!$B$15:$B$500,MATCH(A16,'Historical WTI Data'!$A$15:$A$500,0)) -> 89.43 | C16: =BasisAssumed - (ROW()-14)*0.02 + 0.3*SIN((ROW()-14)/3) -> -1.3544891 | D16: =B16+C16 -> 88.075511 | E16: =ProdForecast -> 50000 | F16: =E16*ActualPct -> 46000 | G16: =HedgePct -> 0.85 | H16: =E16*G16 -> 42500 | I16: =MAX(H16-F16,0) -> 0 | J16: =F16*D16 -> 4051473.5 | K16: =J16 -> 4051473.5 | L16: =H16*(SwapPrice-B16) -> -613275 | M16: =J16+L16 -> 3438198.5 | N16: =H16*(BasisLocked-C16) -> 15065.785 | O16: =J16+L16+N16 -> 3453264.3 | P16: =IF(F16=0,0,K16/F16) -> 88.075511 | Q16: =IF(F16=0,0,M16/F16) -> 74.743446 | R16: =IF(F16=0,0,O16/F16) -> 75.070963
A17: =EDATE($A$14,3) -> 45200 | B17: =INDEX('Historical WTI Data'!$B$15:$B$500,MATCH(A17,'Historical WTI Data'!$A$15:$A$500,0)) -> 85.64 | C17: =BasisAssumed - (ROW()-14)*0.02 + 0.3*SIN((ROW()-14)/3) -> -1.3075587 | D17: =B17+C17 -> 84.332441 | E17: =ProdForecast -> 50000 | F17: =E17*ActualPct -> 46000 | G17: =HedgePct -> 0.85 | H17: =E17*G17 -> 42500 | I17: =MAX(H17-F17,0) -> 0 | J17: =F17*D17 -> 3879292.3 | K17: =J17 -> 3879292.3 | L17: =H17*(SwapPrice-B17) -> -452200 | M17: =J17+L17 -> 3427092.3 | N17: =H17*(BasisLocked-C17) -> 13071.245 | O17: =J17+L17+N17 -> 3440163.5 | P17: =IF(F17=0,0,K17/F17) -> 84.332441 | Q17: =IF(F17=0,0,M17/F17) -> 74.502007 | R17: =IF(F17=0,0,O17/F17) -> 74.786164
A18: =EDATE($A$14,4) -> 45231 | B18: =INDEX('Historical WTI Data'!$B$15:$B$500,MATCH(A18,'Historical WTI Data'!$A$15:$A$500,0)) -> 77.69 | C18: =BasisAssumed - (ROW()-14)*0.02 + 0.3*SIN((ROW()-14)/3) -> -1.2884186 | D18: =B18+C18 -> 76.401581 | E18: =ProdForecast -> 50000 | F18: =E18*ActualPct -> 46000 | G18: =HedgePct -> 0.85 | H18: =E18*G18 -> 42500 | I18: =MAX(H18-F18,0) -> 0 | J18: =F18*D18 -> 3514472.7 | K18: =J18 -> 3514472.7 | L18: =H18*(SwapPrice-B18) -> -114325 | M18: =J18+L18 -> 3400147.7 | N18: =H18*(BasisLocked-C18) -> 12257.792 | O18: =J18+L18+N18 -> 3412405.5 | P18: =IF(F18=0,0,K18/F18) -> 76.401581 | Q18: =IF(F18=0,0,M18/F18) -> 73.916255 | R18: =IF(F18=0,0,O18/F18) -> 74.182729
A19: =EDATE($A$14,5) -> 45261 | B19: =INDEX('Historical WTI Data'!$B$15:$B$500,MATCH(A19,'Historical WTI Data'!$A$15:$A$500,0)) -> 71.9 | C19: =BasisAssumed - (ROW()-14)*0.02 + 0.3*SIN((ROW()-14)/3) -> -1.3013776 | D19: =B19+C19 -> 70.598622 | E19: =ProdForecast -> 50000 | F19: =E19*ActualPct -> 46000 | G19: =HedgePct -> 0.85 | H19: =E19*G19 -> 42500 | I19: =MAX(H19-F19,0) -> 0 | J19: =F19*D19 -> 3247536.6 | K19: =J19 -> 3247536.6 | L19: =H19*(SwapPrice-B19) -> 131750 | M19: =J19+L19 -> 3379286.6 | N19: =H19*(BasisLocked-C19) -> 12808.549 | O19: =J19+L19+N19 -> 3392095.2 | P19: =IF(F19=0,0,K19/F19) -> 70.598622 | Q19: =IF(F19=0,0,M19/F19) -> 73.462753 | R19: =IF(F19=0,0,O19/F19) -> 73.7412
A20: =EDATE($A$14,6) -> 45292 | B20: =INDEX('Historical WTI Data'!$B$15:$B$500,MATCH(A20,'Historical WTI Data'!$A$15:$A$500,0)) -> 74.15 | C20: =BasisAssumed - (ROW()-14)*0.02 + 0.3*SIN((ROW()-14)/3) -> -1.3472108 | D20: =B20+C20 -> 72.802789 | E20: =ProdForecast -> 50000 | F20: =E20*ActualPct -> 46000 | G20: =HedgePct -> 0.85 | H20: =E20*G20 -> 42500 | I20: =MAX(H20-F20,0) -> 0 | J20: =F20*D20 -> 3348928.3 | K20: =J20 -> 3348928.3 | L20: =H20*(SwapPrice-B20) -> 36125 | M20: =J20+L20 -> 3385053.3 | N20: =H20*(BasisLocked-C20) -> 14756.458 | O20: =J20+L20+N20 -> 3399809.8 | P20: =IF(F20=0,0,K20/F20) -> 72.802789 | Q20: =IF(F20=0,0,M20/F20) -> 73.588115 | R20: =IF(F20=0,0,O20/F20) -> 73.908908
A21: =EDATE($A$14,7) -> 45323 | B21: =INDEX('Historical WTI Data'!$B$15:$B$500,MATCH(A21,'Historical WTI Data'!$A$15:$A$500,0)) -> 77.25 | C21: =BasisAssumed - (ROW()-14)*0.02 + 0.3*SIN((ROW()-14)/3) -> -1.4230742 | D21: =B21+C21 -> 75.826926 | E21: =ProdForecast -> 50000 | F21: =E21*ActualPct -> 46000 | G21: =HedgePct -> 0.85 | H21: =E21*G21 -> 42500 | I21: =MAX(H21-F21,0) -> 0 | J21: =F21*D21 -> 3488038.6 | K21: =J21 -> 3488038.6 | L21: =H21*(SwapPrice-B21) -> -95625 | M21: =J21+L21 -> 3392413.6 | N21: =H21*(BasisLocked-C21) -> 17980.655 | O21: =J21+L21+N21 -> 3410394.2 | P21: =IF(F21=0,0,K21/F21) -> 75.826926 | Q21: =IF(F21=0,0,M21/F21) -> 73.748121 | R21: =IF(F21=0,0,O21/F21) -> 74.139005
A22: =EDATE($A$14,8) -> 45352 | B22: =INDEX('Historical WTI Data'!$B$15:$B$500,MATCH(A22,'Historical WTI Data'!$A$15:$A$500,0)) -> 81.28 | C22: =BasisAssumed - (ROW()-14)*0.02 + 0.3*SIN((ROW()-14)/3) -> -1.5228182 | D22: =B22+C22 -> 79.757182 | E22: =ProdForecast -> 50000 | F22: =E22*ActualPct -> 46000 | G22: =HedgePct -> 0.85 | H22: =E22*G22 -> 42500 | I22: =MAX(H22-F22,0) -> 0 | J22: =F22*D22 -> 3668830.4 | K22: =J22 -> 3668830.4 | L22: =H22*(SwapPrice-B22) -> -266900 | M22: =J22+L22 -> 3401930.4 | N22: =H22*(BasisLocked-C22) -> 22219.774 | O22: =J22+L22+N22 -> 3424150.1 | P22: =IF(F22=0,0,K22/F22) -> 79.757182 | Q22: =IF(F22=0,0,M22/F22) -> 73.955008 | R22: =IF(F22=0,0,O22/F22) -> 74.438046
A23: =EDATE($A$14,9) -> 45383 | B23: =INDEX('Historical WTI Data'!$B$15:$B$500,MATCH(A23,'Historical WTI Data'!$A$15:$A$500,0)) -> 85.35 | C23: =BasisAssumed - (ROW()-14)*0.02 + 0.3*SIN((ROW()-14)/3) -> -1.637664 | D23: =B23+C23 -> 83.712336 | E23: =ProdForecast -> 50000 | F23: =E23*ActualPct -> 46000 | G23: =HedgePct -> 0.85 | H23: =E23*G23 -> 42500 | I23: =MAX(H23-F23,0) -> 0 | J23: =F23*D23 -> 3850767.5 | K23: =J23 -> 3850767.5 | L23: =H23*(SwapPrice-B23) -> -439875 | M23: =J23+L23 -> 3410892.5 | N23: =H23*(BasisLocked-C23) -> 27100.72 | O23: =J23+L23+N23 -> 3437993.2 | P23: =IF(F23=0,0,K23/F23) -> 83.712336 | Q23: =IF(F23=0,0,M23/F23) -> 74.149836 | R23: =IF(F23=0,0,O23/F23) -> 74.738982
A24: =EDATE($A$14,10) -> 45413 | B24: =INDEX('Historical WTI Data'!$B$15:$B$500,MATCH(A24,'Historical WTI Data'!$A$15:$A$500,0)) -> 80.02 | C24: =BasisAssumed - (ROW()-14)*0.02 + 0.3*SIN((ROW()-14)/3) -> -1.7571704 | D24: =B24+C24 -> 78.26283 | E24: =ProdForecast -> 50000 | F24: =E24*ActualPct -> 46000 | G24: =HedgePct -> 0.85 | H24: =E24*G24 -> 42500 | I24: =MAX(H24-F24,0) -> 0 | J24: =F24*D24 -> 3600090.2 | K24: =J24 -> 3600090.2 | L24: =H24*(SwapPrice-B24) -> -213350 | M24: =J24+L24 -> 3386740.2 | N24: =H24*(BasisLocked-C24) -> 32179.742 | O24: =J24+L24+N24 -> 3418919.9 | P24: =IF(F24=0,0,K24/F24) -> 78.26283 | Q24: =IF(F24=0,0,M24/F24) -> 73.624786 | R24: =IF(F24=0,0,O24/F24) -> 74.324346
A25: =EDATE($A$14,11) -> 45444 | B25: =INDEX('Historical WTI Data'!$B$15:$B$500,MATCH(A25,'Historical WTI Data'!$A$15:$A$500,0)) -> 79.77 | C25: =BasisAssumed - (ROW()-14)*0.02 + 0.3*SIN((ROW()-14)/3) -> -1.8703831 | D25: =B25+C25 -> 77.899617 | E25: =ProdForecast -> 50000 | F25: =E25*ActualPct -> 46000 | G25: =HedgePct -> 0.85 | H25: =E25*G25 -> 42500 | I25: =MAX(H25-F25,0) -> 0 | J25: =F25*D25 -> 3583382.4 | K25: =J25 -> 3583382.4 | L25: =H25*(SwapPrice-B25) -> -202725 | M25: =J25+L25 -> 3380657.4 | N25: =H25*(BasisLocked-C25) -> 36991.282 | O25: =J25+L25+N25 -> 3417648.7 | P25: =IF(F25=0,0,K25/F25) -> 77.899617 | Q25: =IF(F25=0,0,M25/F25) -> 73.492552 | R25: =IF(F25=0,0,O25/F25) -> 74.29671
A26: =EDATE($A$14,12) -> 45474 | B26: =INDEX('Historical WTI Data'!$B$15:$B$500,MATCH(A26,'Historical WTI Data'!$A$15:$A$500,0)) -> 81.8 | C26: =BasisAssumed - (ROW()-14)*0.02 + 0.3*SIN((ROW()-14)/3) -> -1.9670407 | D26: =B26+C26 -> 79.832959 | E26: =ProdForecast -> 50000 | F26: =E26*ActualPct -> 46000 | G26: =HedgePct -> 0.85 | H26: =E26*G26 -> 42500 | I26: =MAX(H26-F26,0) -> 0 | J26: =F26*D26 -> 3672316.1 | K26: =J26 -> 3672316.1 | L26: =H26*(SwapPrice-B26) -> -289000 | M26: =J26+L26 -> 3383316.1 | N26: =H26*(BasisLocked-C26) -> 41099.232 | O26: =J26+L26+N26 -> 3424415.4 | P26: =IF(F26=0,0,K26/F26) -> 79.832959 | Q26: =IF(F26=0,0,M26/F26) -> 73.550351 | R26: =IF(F26=0,0,O26/F26) -> 74.443812
A27: =EDATE($A$14,13) -> 45505 | B27: =INDEX('Historical WTI Data'!$B$15:$B$500,MATCH(A27,'Historical WTI Data'!$A$15:$A$500,0)) -> 76.68 | C27: =BasisAssumed - (ROW()-14)*0.02 + 0.3*SIN((ROW()-14)/3) -> -2.0387044 | D27: =B27+C27 -> 74.641296 | E27: =ProdForecast -> 50000 | F27: =E27*ActualPct -> 46000 | G27: =HedgePct -> 0.85 | H27: =E27*G27 -> 42500 | I27: =MAX(H27-F27,0) -> 0 | J27: =F27*D27 -> 3433499.6 | K27: =J27 -> 3433499.6 | L27: =H27*(SwapPrice-B27) -> -71400 | M27: =J27+L27 -> 3362099.6 | N27: =H27*(BasisLocked-C27) -> 44144.935 | O27: =J27+L27+N27 -> 3406244.5 | P27: =IF(F27=0,0,K27/F27) -> 74.641296 | Q27: =IF(F27=0,0,M27/F27) -> 73.089122 | R27: =IF(F27=0,0,O27/F27) -> 74.048794
A28: =EDATE($A$14,14) -> 45536 | B28: =INDEX('Historical WTI Data'!$B$15:$B$500,MATCH(A28,'Historical WTI Data'!$A$15:$A$500,0)) -> 70.24 | C28: =BasisAssumed - (ROW()-14)*0.02 + 0.3*SIN((ROW()-14)/3) -> -2.0796865 | D28: =B28+C28 -> 68.160314 | E28: =ProdForecast -> 50000 | F28: =E28*ActualPct -> 46000 | G28: =HedgePct -> 0.85 | H28: =E28*G28 -> 42500 | I28: =MAX(H28-F28,0) -> 0 | J28: =F28*D28 -> 3135374.4 | K28: =J28 -> 3135374.4 | L28: =H28*(SwapPrice-B28) -> 202300 | M28: =J28+L28 -> 3337674.4 | N28: =H28*(BasisLocked-C28) -> 45886.675 | O28: =J28+L28+N28 -> 3383561.1 | P28: =IF(F28=0,0,K28/F28) -> 68.160314 | Q28: =IF(F28=0,0,M28/F28) -> 72.55814 | R28: =IF(F28=0,0,O28/F28) -> 73.555676
A29: =EDATE($A$14,15) -> 45566 | B29: =INDEX('Historical WTI Data'!$B$15:$B$500,MATCH(A29,'Historical WTI Data'!$A$15:$A$500,0)) -> 71.99 | C29: =BasisAssumed - (ROW()-14)*0.02 + 0.3*SIN((ROW()-14)/3) -> -2.0876773 | D29: =B29+C29 -> 69.902323 | E29: =ProdForecast -> 50000 | F29: =E29*ActualPct -> 46000 | G29: =HedgePct -> 0.85 | H29: =E29*G29 -> 42500 | I29: =MAX(H29-F29,0) -> 0 | J29: =F29*D29 -> 3215506.8 | K29: =J29 -> 3215506.8 | L29: =H29*(SwapPrice-B29) -> 127925 | M29: =J29+L29 -> 3343431.8 | N29: =H29*(BasisLocked-C29) -> 46226.285 | O29: =J29+L29+N29 -> 3389658.1 | P29: =IF(F29=0,0,K29/F29) -> 69.902323 | Q29: =IF(F29=0,0,M29/F29) -> 72.683301 | R29: =IF(F29=0,0,O29/F29) -> 73.68822
A30: =EDATE($A$14,16) -> 45597 | B30: =INDEX('Historical WTI Data'!$B$15:$B$500,MATCH(A30,'Historical WTI Data'!$A$15:$A$500,0)) -> 69.95 | C30: =BasisAssumed - (ROW()-14)*0.02 + 0.3*SIN((ROW()-14)/3) -> -2.0639988 | D30: =B30+C30 -> 67.886001 | E30: =ProdForecast -> 50000 | F30: =E30*ActualPct -> 46000 | G30: =HedgePct -> 0.85 | H30: =E30*G30 -> 42500 | I30: =MAX(H30-F30,0) -> 0 | J30: =F30*D30 -> 3122756.1 | K30: =J30 -> 3122756.1 | L30: =H30*(SwapPrice-B30) -> 214625 | M30: =J30+L30 -> 3337381.1 | N30: =H30*(BasisLocked-C30) -> 45219.95 | O30: =J30+L30+N30 -> 3382601 | P30: =IF(F30=0,0,K30/F30) -> 67.886001 | Q30: =IF(F30=0,0,M30/F30) -> 72.551762 | R30: =IF(F30=0,0,O30/F30) -> 73.534804
A31: =EDATE($A$14,17) -> 45627 | B31: =INDEX('Historical WTI Data'!$B$15:$B$500,MATCH(A31,'Historical WTI Data'!$A$15:$A$500,0)) -> 70.12 | C31: =BasisAssumed - (ROW()-14)*0.02 + 0.3*SIN((ROW()-14)/3) -> -2.0134595 | D31: =B31+C31 -> 68.106541 | E31: =ProdForecast -> 50000 | F31: =E31*ActualPct -> 46000 | G31: =HedgePct -> 0.85 | H31: =E31*G31 -> 42500 | I31: =MAX(H31-F31,0) -> 0 | J31: =F31*D31 -> 3132900.9 | K31: =J31 -> 3132900.9 | L31: =H31*(SwapPrice-B31) -> 207400 | M31: =J31+L31 -> 3340300.9 | N31: =H31*(BasisLocked-C31) -> 43072.028 | O31: =J31+L31+N31 -> 3383372.9 | P31: =IF(F31=0,0,K31/F31) -> 68.106541 | Q31: =IF(F31=0,0,M31/F31) -> 72.615236 | R31: =IF(F31=0,0,O31/F31) -> 73.551585
A32: =EDATE($A$14,18) -> 45658 | B32: =INDEX('Historical WTI Data'!$B$15:$B$500,MATCH(A32,'Historical WTI Data'!$A$15:$A$500,0)) -> 75.74 | C32: =BasisAssumed - (ROW()-14)*0.02 + 0.3*SIN((ROW()-14)/3) -> -1.9438246 | D32: =B32+C32 -> 73.796175 | E32: =ProdForecast -> 50000 | F32: =E32*ActualPct -> 46000 | G32: =HedgePct -> 0.85 | H32: =E32*G32 -> 42500 | I32: =MAX(H32-F32,0) -> 0 | J32: =F32*D32 -> 3394624.1 | K32: =J32 -> 3394624.1 | L32: =H32*(SwapPrice-B32) -> -31450 | M32: =J32+L32 -> 3363174.1 | N32: =H32*(BasisLocked-C32) -> 40112.548 | O32: =J32+L32+N32 -> 3403286.6 | P32: =IF(F32=0,0,K32/F32) -> 73.796175 | Q32: =IF(F32=0,0,M32/F32) -> 73.11248 | R32: =IF(F32=0,0,O32/F32) -> 73.984492
A33: =EDATE($A$14,19) -> 45689 | B33: =INDEX('Historical WTI Data'!$B$15:$B$500,MATCH(A33,'Historical WTI Data'!$A$15:$A$500,0)) -> 71.53 | C33: =BasisAssumed - (ROW()-14)*0.02 + 0.3*SIN((ROW()-14)/3) -> -1.8649619 | D33: =B33+C33 -> 69.665038 | E33: =ProdForecast -> 50000 | F33: =E33*ActualPct -> 46000 | G33: =HedgePct -> 0.85 | H33: =E33*G33 -> 42500 | I33: =MAX(H33-F33,0) -> 0 | J33: =F33*D33 -> 3204591.8 | K33: =J33 -> 3204591.8 | L33: =H33*(SwapPrice-B33) -> 147475 | M33: =J33+L33 -> 3352066.8 | N33: =H33*(BasisLocked-C33) -> 36760.881 | O33: =J33+L33+N33 -> 3388827.6 | P33: =IF(F33=0,0,K33/F33) -> 69.665038 | Q33: =IF(F33=0,0,M33/F33) -> 72.871016 | R33: =IF(F33=0,0,O33/F33) -> 73.670166
A34: =EDATE($A$14,20) -> 45717 | B34: =INDEX('Historical WTI Data'!$B$15:$B$500,MATCH(A34,'Historical WTI Data'!$A$15:$A$500,0)) -> 68.24 | C34: =BasisAssumed - (ROW()-14)*0.02 + 0.3*SIN((ROW()-14)/3) -> -1.7877546 | D34: =B34+C34 -> 66.452245 | E34: =ProdForecast -> 50000 | F34: =E34*ActualPct -> 46000 | G34: =HedgePct -> 0.85 | H34: =E34*G34 -> 42500 | I34: =MAX(H34-F34,0) -> 0 | J34: =F34*D34 -> 3056803.3 | K34: =J34 -> 3056803.3 | L34: =H34*(SwapPrice-B34) -> 287300 | M34: =J34+L34 -> 3344103.3 | N34: =H34*(BasisLocked-C34) -> 33479.572 | O34: =J34+L34+N34 -> 3377582.9 | P34: =IF(F34=0,0,K34/F34) -> 66.452245 | Q34: =IF(F34=0,0,M34/F34) -> 72.697898 | R34: =IF(F34=0,0,O34/F34) -> 73.425714
A35: =EDATE($A$14,21) -> 45748 | B35: =INDEX('Historical WTI Data'!$B$15:$B$500,MATCH(A35,'Historical WTI Data'!$A$15:$A$500,0)) -> 63.54 | C35: =BasisAssumed - (ROW()-14)*0.02 + 0.3*SIN((ROW()-14)/3) -> -1.722904 | D35: =B35+C35 -> 61.817096 | E35: =ProdForecast -> 50000 | F35: =E35*ActualPct -> 46000 | G35: =HedgePct -> 0.85 | H35: =E35*G35 -> 42500 | I35: =MAX(H35-F35,0) -> 0 | J35: =F35*D35 -> 2843586.4 | K35: =J35 -> 2843586.4 | L35: =H35*(SwapPrice-B35) -> 487050 | M35: =J35+L35 -> 3330636.4 | N35: =H35*(BasisLocked-C35) -> 30723.421 | O35: =J35+L35+N35 -> 3361359.8 | P35: =IF(F35=0,0,K35/F35) -> 61.817096 | Q35: =IF(F35=0,0,M35/F35) -> 72.405139 | R35: =IF(F35=0,0,O35/F35) -> 73.07304
A36: =EDATE($A$14,22) -> 45778 | B36: =INDEX('Historical WTI Data'!$B$15:$B$500,MATCH(A36,'Historical WTI Data'!$A$15:$A$500,0)) -> 62.17 | C36: =BasisAssumed - (ROW()-14)*0.02 + 0.3*SIN((ROW()-14)/3) -> -1.6797509 | D36: =B36+C36 -> 60.490249 | E36: =ProdForecast -> 50000 | F36: =E36*ActualPct -> 46000 | G36: =HedgePct -> 0.85 | H36: =E36*G36 -> 42500 | I36: =MAX(H36-F36,0) -> 0 | J36: =F36*D36 -> 2782551.5 | K36: =J36 -> 2782551.5 | L36: =H36*(SwapPrice-B36) -> 545275 | M36: =J36+L36 -> 3327826.5 | N36: =H36*(BasisLocked-C36) -> 28889.415 | O36: =J36+L36+N36 -> 3356715.9 | P36: =IF(F36=0,0,K36/F36) -> 60.490249 | Q36: =IF(F36=0,0,M36/F36) -> 72.344053 | R36: =IF(F36=0,0,O36/F36) -> 72.972084
A37: =EDATE($A$14,23) -> 45809 | B37: =INDEX('Historical WTI Data'!$B$15:$B$500,MATCH(A37,'Historical WTI Data'!$A$15:$A$500,0)) -> 68.17 | C37: =BasisAssumed - (ROW()-14)*0.02 + 0.3*SIN((ROW()-14)/3) -> -1.6652477 | D37: =B37+C37 -> 66.504752 | E37: =ProdForecast -> 50000 | F37: =E37*ActualPct -> 46000 | G37: =HedgePct -> 0.85 | H37: =E37*G37 -> 42500 | I37: =MAX(H37-F37,0) -> 0 | J37: =F37*D37 -> 3059218.6 | K37: =J37 -> 3059218.6 | L37: =H37*(SwapPrice-B37) -> 290275 | M37: =J37+L37 -> 3349493.6 | N37: =H37*(BasisLocked-C37) -> 28273.026 | O37: =J37+L37+N37 -> 3377766.6 | P37: =IF(F37=0,0,K37/F37) -> 66.504752 | Q37: =IF(F37=0,0,M37/F37) -> 72.815078 | R37: =IF(F37=0,0,O37/F37) -> 73.429709
A38: =EDATE($A$14,24) -> 45839 | B38: =INDEX('Historical WTI Data'!$B$15:$B$500,MATCH(A38,'Historical WTI Data'!$A$15:$A$500,0)) -> 68.39 | C38: =BasisAssumed - (ROW()-14)*0.02 + 0.3*SIN((ROW()-14)/3) -> -1.6831925 | D38: =B38+C38 -> 66.706807 | E38: =ProdForecast -> 50000 | F38: =E38*ActualPct -> 46000 | G38: =HedgePct -> 0.85 | H38: =E38*G38 -> 42500 | I38: =MAX(H38-F38,0) -> 0 | J38: =F38*D38 -> 3068513.1 | K38: =J38 -> 3068513.1 | L38: =H38*(SwapPrice-B38) -> 280925 | M38: =J38+L38 -> 3349438.1 | N38: =H38*(BasisLocked-C38) -> 29035.682 | O38: =J38+L38+N38 -> 3378473.8 | P38: =IF(F38=0,0,K38/F38) -> 66.706807 | Q38: =IF(F38=0,0,M38/F38) -> 72.813873 | R38: =IF(F38=0,0,O38/F38) -> 73.445083
A39: =EDATE($A$14,25) -> 45870 | B39: =INDEX('Historical WTI Data'!$B$15:$B$500,MATCH(A39,'Historical WTI Data'!$A$15:$A$500,0)) -> 64.86 | C39: =BasisAssumed - (ROW()-14)*0.02 + 0.3*SIN((ROW()-14)/3) -> -1.7338118 | D39: =B39+C39 -> 63.126188 | E39: =ProdForecast -> 50000 | F39: =E39*ActualPct -> 46000 | G39: =HedgePct -> 0.85 | H39: =E39*G39 -> 42500 | I39: =MAX(H39-F39,0) -> 0 | J39: =F39*D39 -> 2903804.7 | K39: =J39 -> 2903804.7 | L39: =H39*(SwapPrice-B39) -> 430950 | M39: =J39+L39 -> 3334754.7 | N39: =H39*(BasisLocked-C39) -> 31187 | O39: =J39+L39+N39 -> 3365941.7 | P39: =IF(F39=0,0,K39/F39) -> 63.126188 | Q39: =IF(F39=0,0,M39/F39) -> 72.494666 | R39: =IF(F39=0,0,O39/F39) -> 73.172645
A40: =EDATE($A$14,26) -> 45901 | B40: =INDEX('Historical WTI Data'!$B$15:$B$500,MATCH(A40,'Historical WTI Data'!$A$15:$A$500,0)) -> 63.96 | C40: =BasisAssumed - (ROW()-14)*0.02 + 0.3*SIN((ROW()-14)/3) -> -1.8137346 | D40: =B40+C40 -> 62.146265 | E40: =ProdForecast -> 50000 | F40: =E40*ActualPct -> 46000 | G40: =HedgePct -> 0.85 | H40: =E40*G40 -> 42500 | I40: =MAX(H40-F40,0) -> 0 | J40: =F40*D40 -> 2858728.2 | K40: =J40 -> 2858728.2 | L40: =H40*(SwapPrice-B40) -> 469200 | M40: =J40+L40 -> 3327928.2 | N40: =H40*(BasisLocked-C40) -> 34583.722 | O40: =J40+L40+N40 -> 3362511.9 | P40: =IF(F40=0,0,K40/F40) -> 62.146265 | Q40: =IF(F40=0,0,M40/F40) -> 72.346265 | R40: =IF(F40=0,0,O40/F40) -> 73.098085
A41: =EDATE($A$14,27) -> 45931 | B41: =INDEX('Historical WTI Data'!$B$15:$B$500,MATCH(A41,'Historical WTI Data'!$A$15:$A$500,0)) -> 60.89 | C41: =BasisAssumed - (ROW()-14)*0.02 + 0.3*SIN((ROW()-14)/3) -> -1.9163645 | D41: =B41+C41 -> 58.973636 | E41: =ProdForecast -> 50000 | F41: =E41*ActualPct -> 46000 | G41: =HedgePct -> 0.85 | H41: =E41*G41 -> 42500 | I41: =MAX(H41-F41,0) -> 0 | J41: =F41*D41 -> 2712787.2 | K41: =J41 -> 2712787.2 | L41: =H41*(SwapPrice-B41) -> 599675 | M41: =J41+L41 -> 3312462.2 | N41: =H41*(BasisLocked-C41) -> 38945.489 | O41: =J41+L41+N41 -> 3351407.7 | P41: =IF(F41=0,0,K41/F41) -> 58.973636 | Q41: =IF(F41=0,0,M41/F41) -> 72.010049 | R41: =IF(F41=0,0,O41/F41) -> 72.85669
A42: =EDATE($A$14,28) -> 45962 | B42: =INDEX('Historical WTI Data'!$B$15:$B$500,MATCH(A42,'Historical WTI Data'!$A$15:$A$500,0)) -> 60.06 | C42: =BasisAssumed - (ROW()-14)*0.02 + 0.3*SIN((ROW()-14)/3) -> -2.0326048 | D42: =B42+C42 -> 58.027395 | E42: =ProdForecast -> 50000 | F42: =E42*ActualPct -> 46000 | G42: =HedgePct -> 0.85 | H42: =E42*G42 -> 42500 | I42: =MAX(H42-F42,0) -> 0 | J42: =F42*D42 -> 2669260.2 | K42: =J42 -> 2669260.2 | L42: =H42*(SwapPrice-B42) -> 634950 | M42: =J42+L42 -> 3304210.2 | N42: =H42*(BasisLocked-C42) -> 43885.705 | O42: =J42+L42+N42 -> 3348095.9 | P42: =IF(F42=0,0,K42/F42) -> 58.027395 | Q42: =IF(F42=0,0,M42/F42) -> 71.830656 | R42: =IF(F42=0,0,O42/F42) -> 72.784693
...

Sheet Stress Scenarios
A1: Stress Scenarios
A2: Each scenario applies a single shock to the base-case assumptions. The base case uses the average WTI price actually observed over the analysis window.
A4: Base Case Reference Values
A5: Base WTI Cushing price ($/bbl) | B5: =AVERAGE('Hedge Calculations'!B14:B49) -> 74.706389
A6: Base Midland basis ($/bbl) | B6: =BasisAssumed -> -1.5
A7: Base actual production (% of forecast) | B7: =ActualPct -> 0.92
A9: Metric | B9: Base Case | C9: A: WTI Price Decline (-$15/bbl) | D9: B: Midland Basis Weakening (-$5/bbl) | E9: C: Production Shortfall (80% of Forecast) | F9: D: Midland Basis Strengthening (+0.75/bbl
A10: WTI Cushing price ($/bbl) | B10: =$B$5 -> 74.706389 | C10: =$B$5-15 -> 59.706389 | D10: =$B$5 -> 74.706389 | E10: =$B$5 -> 74.706389 | F10: =$B$5 -> 74.706389
A11: Midland basis ($/bbl) | B11: =$B$6 -> -1.5 | C11: =$B$6 -> -1.5 | D11: =$B$6-5 -> -6.5 | E11: =$B$6 -> -1.5 | F11: =$B$6+0.75 -> -0.75
A12: Actual production (% of forecast) | B12: =$B$7 -> 0.92 | C12: =$B$7 -> 0.92 | D12: =$B$7 -> 0.92 | E12: 0.8 | F12: =$B$7 -> 0.92
A13: Midland physical price ($/bbl) | B13: =B10+B11 -> 73.206389 | C13: =C10+C11 -> 58.206389 | D13: =D10+D11 -> 68.206389 | E13: =E10+E11 -> 73.206389 | F13: =F10+F11 -> 73.956389
A14: Actual production (bbl) | B14: =ProdForecast*B12 -> 46000 | C14: =ProdForecast*C12 -> 46000 | D14: =ProdForecast*D12 -> 46000 | E14: =ProdForecast*E12 -> 40000 | F14: =ProdForecast*F12 -> 46000
A15: Hedged volume (bbl) | B15: =ProdForecast*HedgePct -> 42500 | C15: =ProdForecast*HedgePct -> 42500 | D15: =ProdForecast*HedgePct -> 42500 | E15: =ProdForecast*HedgePct -> 42500 | F15: =ProdForecast*HedgePct -> 42500
A16: Over-hedged volume (bbl) | B16: =MAX(B15-B14,0) -> 0 | C16: =MAX(C15-C14,0) -> 0 | D16: =MAX(D15-D14,0) -> 0 | E16: =MAX(E15-E14,0) -> 2500 | F16: =MAX(F15-F14,0) -> 0
A17: Physical revenue ($) | B17: =B14*B13 -> 3367493.9 | C17: =C14*C13 -> 2677493.9 | D17: =D14*D13 -> 3137493.9 | E17: =E14*E13 -> 2928255.6 | F17: =F14*F13 -> 3401993.9
A18: WTI swap P&L ($) | B18: =B15*(SwapPrice-B10) -> 12478.472 | C18: =C15*(SwapPrice-C10) -> 649978.47 | D18: =D15*(SwapPrice-D10) -> 12478.472 | E18: =E15*(SwapPrice-E10) -> 12478.472 | F18: =F15*(SwapPrice-F10) -> 12478.472
A19: Basis hedge P&L ($) | B19: =B15*(BasisLocked-B11) -> 21250 | C19: =C15*(BasisLocked-C11) -> 21250 | D19: =D15*(BasisLocked-D11) -> 233750 | E19: =E15*(BasisLocked-E11) -> 21250 | F19: =F15*(BasisLocked-F11) -> -10625
A20: Unhedged net revenue ($) | B20: =B17 -> 3367493.9 | C20: =C17 -> 2677493.9 | D20: =D17 -> 3137493.9 | E20: =E17 -> 2928255.6 | F20: =F17 -> 3401993.9
A21: WTI swap net revenue ($) | B21: =B17+B18 -> 3379972.4 | C21: =C17+C18 -> 3327472.4 | D21: =D17+D18 -> 3149972.4 | E21: =E17+E18 -> 2940734 | F21: =F17+F18 -> 3414472.4
A22: Combined net revenue ($) | B22: =B17+B18+B19 -> 3401222.4 | C22: =C17+C18+C19 -> 3348722.4 | D22: =D17+D18+D19 -> 3383722.4 | E22: =E17+E18+E19 -> 2961984 | F22: =F17+F18+F19 -> 3403847.4
A23: Unhedged net realized price ($/bbl) | B23: =IF(B14=0,0,B20/B14) -> 73.206389 | C23: =IF(C14=0,0,C20/C14) -> 58.206389 | D23: =IF(D14=0,0,D20/D14) -> 68.206389 | E23: =IF(E14=0,0,E20/E14) -> 73.206389 | F23: =IF(F14=0,0,F20/F14) -> 73.956389
A24: WTI swap net realized price ($/bbl) | B24: =IF(B14=0,0,B21/B14) -> 73.47766 | C24: =IF(C14=0,0,C21/C14) -> 72.336356 | D24: =IF(D14=0,0,D21/D14) -> 68.47766 | E24: =IF(E14=0,0,E21/E14) -> 73.518351 | F24: =IF(F14=0,0,F21/F14) -> 74.22766
A25: Combined net realized price ($/bbl) | B25: =IF(B14=0,0,B22/B14) -> 73.939617 | C25: =IF(C14=0,0,C22/C14) -> 72.798312 | D25: =IF(D14=0,0,D22/D14) -> 73.559182 | E25: =IF(E14=0,0,E22/E14) -> 74.049601 | F25: =IF(F14=0,0,F22/F14) -> 73.996682
A27: Change from Base Case ($)
A28: Metric | B28: Base Case | C28: A: WTI Decline | D28: B: Basis Weakening | E28: C: Production Shortfall
A29: Change in unhedged net revenue | B29: =B20-$B$20 -> 0 | C29: =C20-$B$20 -> -690000 | D29: =D20-$B$20 -> -230000 | E29: =E20-$B$20 -> -439238.33 | F29: =F20-$B$20 -> 34500
A30: Change in WTI swap net revenue | B30: =B21-$B$21 -> 0 | C30: =C21-$B$21 -> -52500 | D30: =D21-$B$21 -> -230000 | E30: =E21-$B$21 -> -439238.33 | F30: =F21-$B$21 -> 34500
A31: Change in combined net revenue | B31: =B22-$B$22 -> 0 | C31: =C22-$B$22 -> -52500 | D31: =D22-$B$22 -> -17500 | E31: =E22-$B$22 -> -439238.33 | F31: =F22-$B$22 -> 2625
A33: Scenario A (WTI decline): the WTI swap gains on hedged volume as WTI falls, offsetting most of the benchmark-price loss on the hedged share of production.
A34: Scenario B (basis weakening): the WTI swap alone does not respond to basis, so unhedged and WTI-swap revenue both fall by the same amount. Only the combined strategy's basis hedge offsets the widening discount.
A35: Scenario C (production shortfall): hedged volume is fixed to forecast production, so when actual production falls short, part of the hedge is no longer backed by physical barrels (over-hedged volume), which can amplify swings in net realized price.
A36: Scenario D (basis strengthening): the basis hedge, locked at -$1.00, now works against the producer as the actual discount narrows to -$0.75 — the combined strategy underperforms the WTI-only swap here, illustrating that a basis hedge is a directional bet, not a one-way protection
